<!-- ======================================================
# Copyright 2019 Google LLC
#
# Licensed under the Apache License, Version 2.0 (the "License");
# you may not use this file except in compliance with the License.
# You may obtain a copy of the License at
#
#      http://www.apache.org/licenses/LICENSE-2.0
#
# Unless required by applicable law or agreed to in writing, software
# distributed under the License is distributed on an "AS IS" BASIS,
# WITHOUT WARRANTIES OR CONDITIONS OF ANY KIND, either express or implied.
# See the License for the specific language governing permissions and
# limitations under the License.
====================================================== -->

<mujoco model="ant">
  <compiler angle="degree" coordinate="local" inertiafromgeom="true"/>
  <option integrator="RK4" timestep="0.01"/>
  <custom>
    <numeric data="0.0 0.0 0.55 1.0 0.0 0.0 0.0 0.0 1.0 0.0 -1.0 0.0 -1.0 0.0 1.0" name="init_qpos"/>
  </custom>
  <default>
    <joint armature="1" damping="1" limited="true"/>
    <geom conaffinity="0" condim="3" density="5.0" friction="1 0.5 0.5" margin="0.01" rgba="0.8 0.6 0.4 1"/>
  </default>
  <asset>
    <texture builtin="gradient" height="100" rgb1="1 1 1" rgb2="0 0 0" type="skybox" width="100"/>
    <texture builtin="flat" height="1278" mark="cross" markrgb="1 1 1" name="texgeom" random="0.01" rgb1="0.8 0.6 0.4" rgb2="0.8 0.6 0.4" type="cube" width="127"/>
    <texture builtin="checker" height="100" name="texplane" rgb1="0 0 0" rgb2="0.8 0.8 0.8" type="2d" width="100"/>
    <material name="MatPlane" reflectance="0.5" shininess="1" specular="1" texrepeat="60 60" texture="texplane"/>
    <material name="geom" texture="texgeom" texuniform="true"/>
  </asset>
  <worldbody>
    <light cutoff="100" diffuse="1 1 1" dir="-0 0 -1.3" directional="true" exponent="1" pos="0 0 1.3" specular=".1 .1 .1"/>
    <geom conaffinity="1" condim="3" material="MatPlane" name="floor" pos="0 0 0" rgba="0.8 0.9 0.8 1" size="40 40 40" type="plane"/>
    <camera name="fixed"  pos="-30 30 30" xyaxes="-1 -1 0 1 0 1" mode="fixed" fovy="60"/>
    <body name="torso" pos="0 0 0.75">
      <!-- <camera name="track" mode="trackcom" pos="0 -3 0.3" xyaxes="1 0 0 0 0 1"/> -->
      <!-- <camera name="track"  pos="-5 5 5" xyaxes="-1 -1 0 1 0 1" mode="trackcom"/> -->
      <geom name="torso_geom" pos="0 0 0" size="0.25" type="sphere"/>
      <joint armature="0" damping="0" limited="false" margin="0.01" name="root" pos="0 0 0" type="free"/>
      <body name="front_left_leg" pos="0 0 0">
        <geom fromto="0.0 0.0 0.0 0.2 0.2 0.0" name="aux_1_geom" size="0.08" type="capsule"/>
        <body name="aux_1" pos="0.2 0.2 0">
          <joint axis="0 0 1" name="hip_1" pos="0.0 0.0 0.0" range="-30 30" type="hinge"/>
          <geom fromto="0.0 0.0 0.0 0.2 0.2 0.0" name="left_leg_geom" size="0.08" type="capsule"/>
          <body pos="0.2 0.2 0">
            <joint axis="-1 1 0" name="ankle_1" pos="0.0 0.0 0.0" range="30 70" type="hinge"/>
            <geom fromto="0.0 0.0 0.0 0.4 0.4 0.0" name="left_ankle_geom" size="0.08" type="capsule"/>
          </body>
        </body>
      </body>
      <body name="front_right_leg" pos="0 0 0">
        <geom fromto="0.0 0.0 0.0 -0.2 0.2 0.0" name="aux_2_geom" size="0.08" type="capsule"/>
        <body name="aux_2" pos="-0.2 0.2 0">
          <joint axis="0 0 1" name="hip_2" pos="0.0 0.0 0.0" range="-30 30" type="hinge"/>
          <geom fromto="0.0 0.0 0.0 -0.2 0.2 0.0" name="right_leg_geom" size="0.08" type="capsule"/>
          <body pos="-0.2 0.2 0">
            <joint axis="1 1 0" name="ankle_2" pos="0.0 0.0 0.0" range="-70 -30" type="hinge"/>
            <geom fromto="0.0 0.0 0.0 -0.4 0.4 0.0" name="right_ankle_geom" size="0.08" type="capsule"/>
          </body>
        </body>
      </body>
      <body name="back_leg" pos="0 0 0">
        <geom fromto="0.0 0.0 0.0 -0.2 -0.2 0.0" name="aux_3_geom" size="0.08" type="capsule"/>
        <body name="aux_3" pos="-0.2 -0.2 0">
          <joint axis="0 0 1" name="hip_3" pos="0.0 0.0 0.0" range="-30 30" type="hinge"/>
          <geom fromto="0.0 0.0 0.0 -0.2 -0.2 0.0" name="back_leg_geom" size="0.08" type="capsule"/>
          <body pos="-0.2 -0.2 0">
            <joint axis="-1 1 0" name="ankle_3" pos="0.0 0.0 0.0" range="-70 -30" type="hinge"/>
            <geom fromto="0.0 0.0 0.0 -0.4 -0.4 0.0" name="third_ankle_geom" size="0.08" type="capsule"/>
          </body>
        </body>
      </body>
      <body name="right_back_leg" pos="0 0 0">
        <geom fromto="0.0 0.0 0.0 0.2 -0.2 0.0" name="aux_4_geom" size="0.08" type="capsule"/>
        <body name="aux_4" pos="0.2 -0.2 0">
          <joint axis="0 0 1" name="hip_4" pos="0.0 0.0 0.0" range="-30 30" type="hinge"/>
          <geom fromto="0.0 0.0 0.0 0.2 -0.2 0.0" name="rightback_leg_geom" size="0.08" type="capsule"/>
          <body pos="0.2 -0.2 0">
            <joint axis="1 1 0" name="ankle_4" pos="0.0 0.0 0.0" range="30 70" type="hinge"/>
            <geom fromto="0.0 0.0 0.0 0.4 -0.4 0.0" name="fourth_ankle_geom" size="0.08" type="capsule"/>
          </body>
        </body>
      </body>
    </body>

    <body name="block_0" pos="10 10 -4">
      <geom name="blocky_boi_0" pos="0 0 0" size="3" rgba="0.0 0.0 1.0 0.25" conaffinity="1" type="sphere"/>
    </body>
    <body name="block_1" pos="10 10 -4">
      <geom name="blocky_boi_1" pos="0 0 0" size="3" rgba="0.0 0.0 1.0 0.25" conaffinity="1" type="sphere"/>
    </body>
    <body name="block_2" pos="10 10 -4">
      <geom name="blocky_boi_2" pos="0 0 0" size="3" rgba="0.0 0.0 1.0 0.25" conaffinity="1" type="sphere"/>
    </body>
    <body name="block_3" pos="10 10 -4">
      <geom name="blocky_boi_3" pos="0 0 0" size="3" rgba="0.0 0.0 1.0 0.25" conaffinity="1" type="sphere"/>
    </body>
    <body name="block_4" pos="10 10 -4">
      <geom name="blocky_boi_4" pos="0 0 0" size="3" rgba="0.0 0.0 1.0 0.25" conaffinity="1" type="sphere"/>
    </body>
    <body name="block_5" pos="10 10 -4">
      <geom name="blocky_boi_5" pos="0 0 0" size="3" rgba="0.0 0.0 1.0 0.25" conaffinity="1" type="sphere"/>
    </body>
    <body name="block_6" pos="10 10 -4">
      <geom name="blocky_boi_6" pos="0 0 0" size="3" rgba="0.0 0.0 1.0 0.25" conaffinity="1" type="sphere"/>
    </body>
    <body name="block_7" pos="10 10 -4">
      <geom name="blocky_boi_7" pos="0 0 0" size="3" rgba="0.0 0.0 1.0 0.25" conaffinity="1" type="sphere"/>
    </body>
    <body name="block_8" pos="10 10 -4">
      <geom name="blocky_boi_8" pos="0 0 0" size="3" rgba="0.0 0.0 1.0 0.25" conaffinity="1" type="sphere"/>
    </body>
    <body name="block_9" pos="10 10 -4">
      <geom name="blocky_boi_9" pos="0 0 0" size="3" rgba="0.0 0.0 1.0 0.25" conaffinity="1" type="sphere"/>
    </body>
    <body name="block_10" pos="10 10 -4">
      <geom name="blocky_boi_10" pos="0 0 0" size="3" rgba="0.0 0.0 1.0 0.25" conaffinity="1" type="sphere"/>
    </body>
    <body name="block_11" pos="10 10 -4">
      <geom name="blocky_boi_11" pos="0 0 0" size="3" rgba="0.0 0.0 1.0 0.25" conaffinity="1" type="sphere"/>
    </body>
    <body name="block_12" pos="10 10 -4">
      <geom name="blocky_boi_12" pos="0 0 0" size="3" rgba="0.0 0.0 1.0 0.25" conaffinity="1" type="sphere"/>
    </body>
    <body name="block_13" pos="10 10 -4">
      <geom name="blocky_boi_13" pos="0 0 0" size="3" rgba="0.0 0.0 1.0 0.25" conaffinity="1" type="sphere"/>
    </body>
    <body name="block_14" pos="10 10 -4">
      <geom name="blocky_boi_14" pos="0 0 0" size="3" rgba="0.0 0.0 1.0 0.25" conaffinity="1" type="sphere"/>
    </body>
    <body name="block_15" pos="10 10 -4">
      <geom name="blocky_boi_15" pos="0 0 0" size="3" rgba="0.0 0.0 1.0 0.25" conaffinity="1" type="sphere"/>
    </body>
    <body name="block_16" pos="10 10 -4">
      <geom name="blocky_boi_16" pos="0 0 0" size="3" rgba="0.0 0.0 1.0 0.25" conaffinity="1" type="sphere"/>
    </body>
    <body name="block_17" pos="10 10 -4">
      <geom name="blocky_boi_17" pos="0 0 0" size="3" rgba="0.0 0.0 1.0 0.25" conaffinity="1" type="sphere"/>
    </body>
    <body name="block_18" pos="10 10 -4">
      <geom name="blocky_boi_18" pos="0 0 0" size="3" rgba="0.0 0.0 1.0 0.25" conaffinity="1" type="sphere"/>
    </body>
    <body name="block_19" pos="10 10 -4">
      <geom name="blocky_boi_19" pos="0 0 0" size="3" rgba="0.0 0.0 1.0 0.25" conaffinity="1" type="sphere"/>
    </body>
    <body name="block_20" pos="10 10 -4">
      <geom name="blocky_boi_20" pos="0 0 0" size="3" rgba="0.0 0.0 1.0 0.25" conaffinity="1" type="sphere"/>
    </body>
    <body name="block_21" pos="10 10 -4">
      <geom name="blocky_boi_21" pos="0 0 0" size="3" rgba="0.0 0.0 1.0 0.25" conaffinity="1" type="sphere"/>
    </body>
    <body name="block_22" pos="10 10 -4">
      <geom name="blocky_boi_22" pos="0 0 0" size="3" rgba="0.0 0.0 1.0 0.25" conaffinity="1" type="sphere"/>
    </body>
    <body name="block_23" pos="10 10 -4">
      <geom name="blocky_boi_23" pos="0 0 0" size="3" rgba="0.0 0.0 1.0 0.25" conaffinity="1" type="sphere"/>
    </body>
    <body name="block_24" pos="10 10 -4">
      <geom name="blocky_boi_24" pos="0 0 0" size="3" rgba="0.0 0.0 1.0 0.25" conaffinity="1" type="sphere"/>
    </body>
    <body name="block_25" pos="10 10 -4">
      <geom name="blocky_boi_25" pos="0 0 0" size="3" rgba="0.0 0.0 1.0 0.25" conaffinity="1" type="sphere"/>
    </body>
    <body name="block_26" pos="10 10 -4">
      <geom name="blocky_boi_26" pos="0 0 0" size="3" rgba="0.0 0.0 1.0 0.25" conaffinity="1" type="sphere"/>
    </body>
    <body name="block_27" pos="10 10 -4">
      <geom name="blocky_boi_27" pos="0 0 0" size="3" rgba="0.0 0.0 1.0 0.25" conaffinity="1" type="sphere"/>
    </body>
    <body name="block_28" pos="10 10 -4">
      <geom name="blocky_boi_28" pos="0 0 0" size="3" rgba="0.0 0.0 1.0 0.25" conaffinity="1" type="sphere"/>
    </body>
    <body name="block_29" pos="10 10 -4">
      <geom name="blocky_boi_29" pos="0 0 0" size="3" rgba="0.0 0.0 1.0 0.25" conaffinity="1" type="sphere"/>
    </body>
    <body name="block_30" pos="10 10 -4">
      <geom name="blocky_boi_30" pos="0 0 0" size="3" rgba="0.0 0.0 1.0 0.25" conaffinity="1" type="sphere"/>
    </body>
    <body name="block_31" pos="10 10 -4">
      <geom name="blocky_boi_31" pos="0 0 0" size="3" rgba="0.0 0.0 1.0 0.25" conaffinity="1" type="sphere"/>
    </body>
    <body name="block_32" pos="10 10 -4">
      <geom name="blocky_boi_32" pos="0 0 0" size="3" rgba="0.0 0.0 1.0 0.25" conaffinity="1" type="sphere"/>
    </body>
    <body name="block_33" pos="10 10 -4">
      <geom name="blocky_boi_33" pos="0 0 0" size="3" rgba="0.0 0.0 1.0 0.25" conaffinity="1" type="sphere"/>
    </body>
    <body name="block_34" pos="10 10 -4">
      <geom name="blocky_boi_34" pos="0 0 0" size="3" rgba="0.0 0.0 1.0 0.25" conaffinity="1" type="sphere"/>
    </body>
    <body name="block_35" pos="10 10 -4">
      <geom name="blocky_boi_35" pos="0 0 0" size="3" rgba="0.0 0.0 1.0 0.25" conaffinity="1" type="sphere"/>
    </body>
    <body name="block_36" pos="10 10 -4">
      <geom name="blocky_boi_36" pos="0 0 0" size="3" rgba="0.0 0.0 1.0 0.25" conaffinity="1" type="sphere"/>
    </body>
    <body name="block_37" pos="10 10 -4">
      <geom name="blocky_boi_37" pos="0 0 0" size="3" rgba="0.0 0.0 1.0 0.25" conaffinity="1" type="sphere"/>
    </body>
    <body name="block_38" pos="10 10 -4">
      <geom name="blocky_boi_38" pos="0 0 0" size="3" rgba="0.0 0.0 1.0 0.25" conaffinity="1" type="sphere"/>
    </body>
    <body name="block_39" pos="10 10 -4">
      <geom name="blocky_boi_39" pos="0 0 0" size="3" rgba="0.0 0.0 1.0 0.25" conaffinity="1" type="sphere"/>
    </body>
  </worldbody>
  <actuator>
    <motor ctrllimited="true" ctrlrange="-1.0 1.0" joint="hip_4" gear="150"/>
    <motor ctrllimited="true" ctrlrange="-1.0 1.0" joint="ankle_4" gear="150"/>
    <motor ctrllimited="true" ctrlrange="-1.0 1.0" joint="hip_1" gear="150"/>
    <motor ctrllimited="true" ctrlrange="-1.0 1.0" joint="ankle_1" gear="150"/>
    <motor ctrllimited="true" ctrlrange="-1.0 1.0" joint="hip_2" gear="150"/>
    <motor ctrllimited="true" ctrlrange="-1.0 1.0" joint="ankle_2" gear="150"/>
    <motor ctrllimited="true" ctrlrange="-1.0 1.0" joint="hip_3" gear="150"/>
    <motor ctrllimited="true" ctrlrange="-1.0 1.0" joint="ankle_3" gear="150"/>
  </actuator>
</mujoco>
